<?xml version="1.0" ?>
<robot name="Meta_arm_R" xmlns:xacro="http://www.ros.org/wiki/xacro">

<xacro:include filename="$(find Meta_arm_R_description)/urdf/materials.xacro" />
<xacro:include filename="$(find Meta_arm_R_description)/urdf/Meta_arm_R.trans" />
<xacro:include filename="$(find Meta_arm_R_description)/urdf/Meta_arm_R.gazebo" />
<link name="base_link">
  <inertial>
    <origin xyz="-0.3312641243721142 0.30870397524857063 -0.05585487339132518" rpy="0 0 0"/>
    <mass value="0.07507921631617756"/>
    <inertia ixx="3.4e-05" iyy="5.7e-05" izz="5.2e-05" ixy="-0.0" iyz="-0.0" ixz="-0.0"/>
  </inertial>
  <visual>
    <origin xyz="0 0 0" rpy="0 0 0"/>
    <geometry>
      <mesh filename="package://Meta_arm_R_description/meshes/base_link.stl" scale="0.001 0.001 0.001"/>
    </geometry>
    <material name="silver"/>
  </visual>
  <collision>
    <origin xyz="0 0 0" rpy="0 0 0"/>
    <geometry>
      <mesh filename="package://Meta_arm_R_description/meshes/base_link.stl" scale="0.001 0.001 0.001"/>
    </geometry>
  </collision>
</link>

<link name="link1_1">
  <inertial>
    <origin xyz="0.00031247585312027537 -0.020402188945389366 0.027087588289717034" rpy="0 0 0"/>
    <mass value="0.09072799201107642"/>
    <inertia ixx="5.6e-05" iyy="4e-05" izz="5.8e-05" ixy="1e-06" iyz="1e-06" ixz="-0.0"/>
  </inertial>
  <visual>
    <origin xyz="0.331274 -0.319509 0.028843" rpy="0 0 0"/>
    <geometry>
      <mesh filename="package://Meta_arm_R_description/meshes/link1_1.stl" scale="0.001 0.001 0.001"/>
    </geometry>
    <material name="silver"/>
  </visual>
  <collision>
    <origin xyz="0.331274 -0.319509 0.028843" rpy="0 0 0"/>
    <geometry>
      <mesh filename="package://Meta_arm_R_description/meshes/link1_1.stl" scale="0.001 0.001 0.001"/>
    </geometry>
  </collision>
</link>

<link name="link2_1">
  <inertial>
    <origin xyz="-0.019099777679982055 -0.07379468679874154 -0.0008758525302789168" rpy="0 0 0"/>
    <mass value="0.1471165597971976"/>
    <inertia ixx="0.000149" iyy="0.000101" izz="0.000156" ixy="0.0" iyz="-2e-06" ixz="-0.0"/>
  </inertial>
  <visual>
    <origin xyz="0.311202 -0.271154 0.001139" rpy="0 0 0"/>
    <geometry>
      <mesh filename="package://Meta_arm_R_description/meshes/link2_1.stl" scale="0.001 0.001 0.001"/>
    </geometry>
    <material name="silver"/>
  </visual>
  <collision>
    <origin xyz="0.311202 -0.271154 0.001139" rpy="0 0 0"/>
    <geometry>
      <mesh filename="package://Meta_arm_R_description/meshes/link2_1.stl" scale="0.001 0.001 0.001"/>
    </geometry>
  </collision>
</link>

<link name="link3_1">
  <inertial>
    <origin xyz="-0.0012432407059169148 -0.10490521211286019 0.0008507627627961211" rpy="0 0 0"/>
    <mass value="0.107064701992621"/>
    <inertia ixx="0.000397" iyy="6.8e-05" izz="0.000397" ixy="-6e-06" iyz="4e-06" ixz="-0.0"/>
  </inertial>
  <visual>
    <origin xyz="0.330245 -0.165127 0.000694" rpy="0 0 0"/>
    <geometry>
      <mesh filename="package://Meta_arm_R_description/meshes/link3_1.stl" scale="0.001 0.001 0.001"/>
    </geometry>
    <material name="silver"/>
  </visual>
  <collision>
    <origin xyz="0.330245 -0.165127 0.000694" rpy="0 0 0"/>
    <geometry>
      <mesh filename="package://Meta_arm_R_description/meshes/link3_1.stl" scale="0.001 0.001 0.001"/>
    </geometry>
  </collision>
</link>

<link name="link4_1">
  <inertial>
    <origin xyz="0.07828568739927477 -0.0031763836143609324 -0.020977037579631326" rpy="0 0 0"/>
    <mass value="0.13281320983548392"/>
    <inertia ixx="8.9e-05" iyy="0.000117" izz="0.000114" ixy="-6e-06" iyz="0.0" ixz="0.0"/>
  </inertial>
  <visual>
    <origin xyz="0.33 0.000401 -0.021002" rpy="0 0 0"/>
    <geometry>
      <mesh filename="package://Meta_arm_R_description/meshes/link4_1.stl" scale="0.001 0.001 0.001"/>
    </geometry>
    <material name="silver"/>
  </visual>
  <collision>
    <origin xyz="0.33 0.000401 -0.021002" rpy="0 0 0"/>
    <geometry>
      <mesh filename="package://Meta_arm_R_description/meshes/link4_1.stl" scale="0.001 0.001 0.001"/>
    </geometry>
  </collision>
</link>

<link name="link5_1">
  <inertial>
    <origin xyz="0.1172342013372355 0.00015775532387740085 -0.00047597503738047383" rpy="0 0 0"/>
    <mass value="0.09445026816347044"/>
    <inertia ixx="6e-05" iyy="0.000489" izz="0.000487" ixy="-1e-06" iyz="-0.0" ixz="3e-06"/>
  </inertial>
  <visual>
    <origin xyz="0.224 0.000332 -1e-06" rpy="0 0 0"/>
    <geometry>
      <mesh filename="package://Meta_arm_R_description/meshes/link5_1.stl" scale="0.001 0.001 0.001"/>
    </geometry>
    <material name="silver"/>
  </visual>
  <collision>
    <origin xyz="0.224 0.000332 -1e-06" rpy="0 0 0"/>
    <geometry>
      <mesh filename="package://Meta_arm_R_description/meshes/link5_1.stl" scale="0.001 0.001 0.001"/>
    </geometry>
  </collision>
</link>

<link name="link6_1">
  <inertial>
    <origin xyz="0.01853965708835748 0.0001156099432296103 0.0210001222206634" rpy="0 0 0"/>
    <mass value="0.029206480233661163"/>
    <inertia ixx="2.3e-05" iyy="2.4e-05" izz="1.1e-05" ixy="-0.0" iyz="-0.0" ixz="-0.0"/>
  </inertial>
  <visual>
    <origin xyz="0.035 0.00014 0.021" rpy="0 0 0"/>
    <geometry>
      <mesh filename="package://Meta_arm_R_description/meshes/link6_1.stl" scale="0.001 0.001 0.001"/>
    </geometry>
    <material name="silver"/>
  </visual>
  <collision>
    <origin xyz="0.035 0.00014 0.021" rpy="0 0 0"/>
    <geometry>
      <mesh filename="package://Meta_arm_R_description/meshes/link6_1.stl" scale="0.001 0.001 0.001"/>
    </geometry>
  </collision>
</link>

<link name="point_1">
  <inertial>
    <origin xyz="0.0012867756901669193 1.9059888775004724e-06 -1.569636595033508e-07" rpy="0 0 0"/>
    <mass value="0.0006569528428977276"/>
    <inertia ixx="0.0" iyy="0.0" izz="0.0" ixy="0.0" iyz="0.0" ixz="0.0"/>
  </inertial>
  <visual>
    <origin xyz="-0.0 -0.0 0.0" rpy="0 0 0"/>
    <geometry>
      <mesh filename="package://Meta_arm_R_description/meshes/point_1.stl" scale="0.001 0.001 0.001"/>
    </geometry>
    <material name="silver"/>
  </visual>
  <collision>
    <origin xyz="-0.0 -0.0 0.0" rpy="0 0 0"/>
    <geometry>
      <mesh filename="package://Meta_arm_R_description/meshes/point_1.stl" scale="0.001 0.001 0.001"/>
    </geometry>
  </collision>
</link>

<joint name="joint1" type="revolute">
  <origin xyz="-0.331274 0.319509 -0.028843" rpy="0 0 0"/>
  <parent link="base_link"/>
  <child link="link1_1"/>
  <axis xyz="0.0 0.004202 0.999991"/>
  <limit upper="1.570796" lower="-1.570796" effort="100" velocity="100"/>
</joint>

<joint name="joint2" type="revolute">
  <origin xyz="0.020072 -0.048355 0.027704" rpy="0 0 0"/>
  <parent link="link1_1"/>
  <child link="link2_1"/>
  <axis xyz="0.999999 0.001482 -6e-06"/>
  <limit upper="0.0" lower="-1.570796" effort="100" velocity="100"/>
</joint>

<joint name="joint3" type="revolute">
  <origin xyz="-0.019043 -0.106027 0.000445" rpy="0 0 0"/>
  <parent link="link2_1"/>
  <child link="link3_1"/>
  <axis xyz="-0.001482 0.99999 -0.004202"/>
  <limit upper="2.617994" lower="-2.617994" effort="100" velocity="100"/>
</joint>

<joint name="joint4" type="revolute">
  <origin xyz="0.000245 -0.165528 0.021696" rpy="0 0 0"/>
  <parent link="link3_1"/>
  <child link="link4_1"/>
  <axis xyz="0.0 0.004202 0.999991"/>
  <limit upper="0.610866" lower="-1.570796" effort="100" velocity="100"/>
</joint>

<joint name="joint5" type="revolute">
  <origin xyz="0.106 6.9e-05 -0.021001" rpy="0 0 0"/>
  <parent link="link4_1"/>
  <child link="link5_1"/>
  <axis xyz="-0.999999 -0.001482 6e-06"/>
  <limit upper="2.617994" lower="-2.617994" effort="100" velocity="100"/>
</joint>

<joint name="joint6" type="revolute">
  <origin xyz="0.189 0.000192 -0.021001" rpy="0 0 0"/>
  <parent link="link5_1"/>
  <child link="link6_1"/>
  <axis xyz="-0.0 -0.004202 -0.999991"/>
  <limit upper="1.570796" lower="-1.570796" effort="100" velocity="100"/>
</joint>

<joint name="point" type="fixed">
  <origin xyz="0.035 0.00014 0.021" rpy="0 0 0"/>
  <parent link="link6_1"/>
  <child link="point_1"/>
  <axis xyz="0.999999 0.001482 -6e-06"/>
  <limit upper="0.001745" lower="0.0" effort="100" velocity="100"/>
</joint>

</robot>
