<?xml version="1.0" ?>
<robot name="Meta_arm_L" xmlns:xacro="http://www.ros.org/wiki/xacro">

<xacro:include filename="$(find Meta_arm_L_description)/urdf/materials.xacro" />
<xacro:include filename="$(find Meta_arm_L_description)/urdf/Meta_arm_L.trans" />
<xacro:include filename="$(find Meta_arm_L_description)/urdf/Meta_arm_L.gazebo" />
<link name="base_link">
  <inertial>
    <origin xyz="-0.33328875063083674 0.30962217416987814 0.05141682472682719" rpy="0 0 0"/>
    <mass value="0.07507921631617756"/>
    <inertia ixx="3.4e-05" iyy="5.7e-05" izz="5.2e-05" ixy="0.0" iyz="0.0" ixz="-0.0"/>
  </inertial>
  <visual>
    <origin xyz="0 0 0" rpy="0 0 0"/>
    <geometry>
      <mesh filename="package://Meta_arm_L_description/meshes/base_link.stl" scale="0.001 0.001 0.001"/>
    </geometry>
    <material name="silver"/>
  </visual>
  <collision>
    <origin xyz="0 0 0" rpy="0 0 0"/>
    <geometry>
      <mesh filename="package://Meta_arm_L_description/meshes/base_link.stl" scale="0.001 0.001 0.001"/>
    </geometry>
  </collision>
</link>

<link name="link1_1">
  <inertial>
    <origin xyz="0.0005001717814695494 -0.020610328537644496 -0.026930416340882047" rpy="0 0 0"/>
    <mass value="0.09072802323891821"/>
    <inertia ixx="5.6e-05" iyy="4e-05" izz="5.8e-05" ixy="1e-06" iyz="-1e-06" ixz="0.0"/>
  </inertial>
  <visual>
    <origin xyz="0.333295 -0.320219 -0.024323" rpy="0 0 0"/>
    <geometry>
      <mesh filename="package://Meta_arm_L_description/meshes/link1_1.stl" scale="0.001 0.001 0.001"/>
    </geometry>
    <material name="silver"/>
  </visual>
  <collision>
    <origin xyz="0.333295 -0.320219 -0.024323" rpy="0 0 0"/>
    <geometry>
      <mesh filename="package://Meta_arm_L_description/meshes/link1_1.stl" scale="0.001 0.001 0.001"/>
    </geometry>
  </collision>
</link>

<link name="link2_1">
  <inertial>
    <origin xyz="-0.019192184742943874 -0.07375769719929967 0.0014429596962129757" rpy="0 0 0"/>
    <mass value="0.1471165597971976"/>
    <inertia ixx="0.000149" iyy="0.000101" izz="0.000156" ixy="0.0" iyz="2e-06" ixz="-0.0"/>
  </inertial>
  <visual>
    <origin xyz="0.313296 -0.271623 0.003008" rpy="0 0 0"/>
    <geometry>
      <mesh filename="package://Meta_arm_L_description/meshes/link2_1.stl" scale="0.001 0.001 0.001"/>
    </geometry>
    <material name="silver"/>
  </visual>
  <collision>
    <origin xyz="0.313296 -0.271623 0.003008" rpy="0 0 0"/>
    <geometry>
      <mesh filename="package://Meta_arm_L_description/meshes/link2_1.stl" scale="0.001 0.001 0.001"/>
    </geometry>
  </collision>
</link>

<link name="link3_1">
  <inertial>
    <origin xyz="-0.001427254193987093 -0.10491003326834535 -6.838068041848614e-05" rpy="0 0 0"/>
    <mass value="0.10706627889201703"/>
    <inertia ixx="0.000397" iyy="6.8e-05" izz="0.000397" ixy="-6e-06" iyz="-1e-06" ixz="0.0"/>
  </inertial>
  <visual>
    <origin xyz="0.332498 -0.165624 0.002638" rpy="0 0 0"/>
    <geometry>
      <mesh filename="package://Meta_arm_L_description/meshes/link3_1.stl" scale="0.001 0.001 0.001"/>
    </geometry>
    <material name="silver"/>
  </visual>
  <collision>
    <origin xyz="0.332498 -0.165624 0.002638" rpy="0 0 0"/>
    <geometry>
      <mesh filename="package://Meta_arm_L_description/meshes/link3_1.stl" scale="0.001 0.001 0.001"/>
    </geometry>
  </collision>
</link>

<link name="link4_1">
  <inertial>
    <origin xyz="0.07814907320248449 -0.003130881138898635 0.021503328846025793" rpy="0 0 0"/>
    <mass value="0.13281320983548392"/>
    <inertia ixx="8.9e-05" iyy="0.000117" izz="0.000114" ixy="-6e-06" iyz="-0.0" ixz="-0.0"/>
  </inertial>
  <visual>
    <origin xyz="0.332391 7.5e-05 0.02305" rpy="0 0 0"/>
    <geometry>
      <mesh filename="package://Meta_arm_L_description/meshes/link4_1.stl" scale="0.001 0.001 0.001"/>
    </geometry>
    <material name="silver"/>
  </visual>
  <collision>
    <origin xyz="0.332391 7.5e-05 0.02305" rpy="0 0 0"/>
    <geometry>
      <mesh filename="package://Meta_arm_L_description/meshes/link4_1.stl" scale="0.001 0.001 0.001"/>
    </geometry>
  </collision>
</link>

<link name="link5_1">
  <inertial>
    <origin xyz="0.1172289147796068 1.5261168174093082e-05 0.0011987009737727272" rpy="0 0 0"/>
    <mass value="0.09445026816347044"/>
    <inertia ixx="6e-05" iyy="0.000489" izz="0.000487" ixy="-0.0" iyz="-0.0" ixz="-5e-06"/>
  </inertial>
  <visual>
    <origin xyz="0.226523 1e-06 0.001397" rpy="0 0 0"/>
    <geometry>
      <mesh filename="package://Meta_arm_L_description/meshes/link5_1.stl" scale="0.001 0.001 0.001"/>
    </geometry>
    <material name="silver"/>
  </visual>
  <collision>
    <origin xyz="0.226523 1e-06 0.001397" rpy="0 0 0"/>
    <geometry>
      <mesh filename="package://Meta_arm_L_description/meshes/link5_1.stl" scale="0.001 0.001 0.001"/>
    </geometry>
  </collision>
</link>

<link name="link6_1">
  <inertial>
    <origin xyz="0.018668706730732707 -7.344937147749836e-05 -0.020885102324875345" rpy="0 0 0"/>
    <mass value="0.029206480233661163"/>
    <inertia ixx="2.3e-05" iyy="2.4e-05" izz="1.1e-05" ixy="0.0" iyz="-0.0" ixz="0.0"/>
  </inertial>
  <visual>
    <origin xyz="0.037656 -7.2e-05 -0.020768" rpy="0 0 0"/>
    <geometry>
      <mesh filename="package://Meta_arm_L_description/meshes/link6_1.stl" scale="0.001 0.001 0.001"/>
    </geometry>
    <material name="silver"/>
  </visual>
  <collision>
    <origin xyz="0.037656 -7.2e-05 -0.020768" rpy="0 0 0"/>
    <geometry>
      <mesh filename="package://Meta_arm_L_description/meshes/link6_1.stl" scale="0.001 0.001 0.001"/>
    </geometry>
  </collision>
</link>

<link name="point_1">
  <inertial>
    <origin xyz="0.0012865063613372682 -4.4990132036747216e-07 8.501953292352023e-06" rpy="0 0 0"/>
    <mass value="0.0006569528428977276"/>
    <inertia ixx="0.0" iyy="0.0" izz="0.0" ixy="-0.0" iyz="0.0" ixz="0.0"/>
  </inertial>
  <visual>
    <origin xyz="0.002527 1e-06 1.6e-05" rpy="0 0 0"/>
    <geometry>
      <mesh filename="package://Meta_arm_L_description/meshes/point_1.stl" scale="0.001 0.001 0.001"/>
    </geometry>
    <material name="silver"/>
  </visual>
  <collision>
    <origin xyz="0.002527 1e-06 1.6e-05" rpy="0 0 0"/>
    <geometry>
      <mesh filename="package://Meta_arm_L_description/meshes/point_1.stl" scale="0.001 0.001 0.001"/>
    </geometry>
  </collision>
</link>

<joint name="joint1" type="revolute">
  <origin xyz="-0.333295 0.320219 0.024323" rpy="0 0 0"/>
  <parent link="base_link"/>
  <child link="link1_1"/>
  <axis xyz="-0.0 -0.003491 -0.999994"/>
  <limit upper="1.570796" lower="-1.570796" effort="100" velocity="100"/>
</joint>

<joint name="joint2" type="revolute">
  <origin xyz="0.019999 -0.048596 -0.027331" rpy="0 0 0"/>
  <parent link="link1_1"/>
  <child link="link2_1"/>
  <axis xyz="1.0 -2.2e-05 0.0"/>
  <limit upper="1.570796" lower="0.0" effort="100" velocity="100"/>
</joint>

<joint name="joint3" type="revolute">
  <origin xyz="-0.019202 -0.105999 0.00037" rpy="0 0 0"/>
  <parent link="link2_1"/>
  <child link="link3_1"/>
  <axis xyz="2.2e-05 0.999994 -0.003491"/>
  <limit upper="2.617994" lower="-2.617994" effort="100" velocity="100"/>
</joint>

<joint name="joint4" type="revolute">
  <origin xyz="0.000107 -0.165699 -0.020412" rpy="0 0 0"/>
  <parent link="link3_1"/>
  <child link="link4_1"/>
  <axis xyz="0.006166 -0.003491 -0.999975"/>
  <limit upper="1.570796" lower="-0.610866" effort="100" velocity="100"/>
</joint>

<joint name="joint5" type="revolute">
  <origin xyz="0.105868 7.4e-05 0.021653" rpy="0 0 0"/>
  <parent link="link4_1"/>
  <child link="link5_1"/>
  <axis xyz="-0.999981 0.0 -0.006166"/>
  <limit upper="2.617994" lower="-2.617994" effort="100" velocity="100"/>
</joint>

<joint name="joint6" type="revolute">
  <origin xyz="0.188867 7.3e-05 0.022165" rpy="0 0 0"/>
  <parent link="link5_1"/>
  <child link="link6_1"/>
  <axis xyz="-0.006166 0.003491 0.999975"/>
  <limit upper="1.570796" lower="-1.570796" effort="100" velocity="100"/>
</joint>

<joint name="point" type="fixed">
  <origin xyz="0.035129 -7.3e-05 -0.020784" rpy="0 0 0"/>
  <parent link="link6_1"/>
  <child link="point_1"/>
  <axis xyz="0.999981 0.0 0.006166"/>
  <limit upper="0.001745" lower="0.0" effort="100" velocity="100"/>
</joint>

</robot>
