<?xml version="1.0" ?>
<robot name="new_meta_R_V22" xmlns:xacro="http://www.ros.org/wiki/xacro">

<xacro:include filename="$(find new_meta_R_V22_description)/urdf/materials.xacro" />
<xacro:include filename="$(find new_meta_R_V22_description)/urdf/new_meta_R_V22.trans" />
<xacro:include filename="$(find new_meta_R_V22_description)/urdf/new_meta_R_V22.gazebo" />
<link name="base_link">
  <inertial>
    <origin xyz="0.21052479080691844 -0.011782609916703468 -0.2571002255597876" rpy="0 0 0"/>
    <mass value="0.042998534330391996"/>
    <inertia ixx="1.1e-05" iyy="7e-06" izz="1.2e-05" ixy="0.0" iyz="0.0" ixz="0.0"/>
  </inertial>
  <visual>
    <origin xyz="0 0 0" rpy="0 0 0"/>
    <geometry>
      <mesh filename="package://new_meta_R_V22_description/meshes/base_link.stl" scale="0.001 0.001 0.001"/>
    </geometry>
    <material name="silver"/>
  </visual>
  <collision>
    <origin xyz="0 0 0" rpy="0 0 0"/>
    <geometry>
      <mesh filename="package://new_meta_R_V22_description/meshes/base_link.stl" scale="0.001 0.001 0.001"/>
    </geometry>
  </collision>
</link>

<link name="link1_1">
  <inertial>
    <origin xyz="-0.01844674531195936 0.0007556981730459398 0.0001976325468944773" rpy="0 0 0"/>
    <mass value="0.04698163433943535"/>
    <inertia ixx="1.4e-05" iyy="1.3e-05" izz="9e-06" ixy="0.0" iyz="-0.0" ixz="0.0"/>
  </inertial>
  <visual>
    <origin xyz="-0.19135 -1e-06 0.2571" rpy="0 0 0"/>
    <geometry>
      <mesh filename="package://new_meta_R_V22_description/meshes/link1_1.stl" scale="0.001 0.001 0.001"/>
    </geometry>
    <material name="silver"/>
  </visual>
  <collision>
    <origin xyz="-0.19135 -1e-06 0.2571" rpy="0 0 0"/>
    <geometry>
      <mesh filename="package://new_meta_R_V22_description/meshes/link1_1.stl" scale="0.001 0.001 0.001"/>
    </geometry>
  </collision>
</link>

<link name="link2_1">
  <inertial>
    <origin xyz="-0.06591511099166311 -0.0312657099347284 -2.414537162523378e-05" rpy="0 0 0"/>
    <mass value="0.054538745902098215"/>
    <inertia ixx="1.5e-05" iyy="2.1e-05" izz="2.8e-05" ixy="-3e-06" iyz="-0.0" ixz="-0.0"/>
  </inertial>
  <visual>
    <origin xyz="-0.17135 -0.020001 0.2451" rpy="0 0 0"/>
    <geometry>
      <mesh filename="package://new_meta_R_V22_description/meshes/link2_1.stl" scale="0.001 0.001 0.001"/>
    </geometry>
    <material name="silver"/>
  </visual>
  <collision>
    <origin xyz="-0.17135 -0.020001 0.2451" rpy="0 0 0"/>
    <geometry>
      <mesh filename="package://new_meta_R_V22_description/meshes/link2_1.stl" scale="0.001 0.001 0.001"/>
    </geometry>
  </collision>
</link>

<link name="link3_1">
  <inertial>
    <origin xyz="-0.059693249313454114 0.0007234685079707573 2.134079862714522e-06" rpy="0 0 0"/>
    <mass value="0.049075913621061326"/>
    <inertia ixx="8e-06" iyy="1.9e-05" izz="2.1e-05" ixy="0.0" iyz="0.0" ixz="-0.0"/>
  </inertial>
  <visual>
    <origin xyz="-0.08025 -0.000501 0.2451" rpy="0 0 0"/>
    <geometry>
      <mesh filename="package://new_meta_R_V22_description/meshes/link3_1.stl" scale="0.001 0.001 0.001"/>
    </geometry>
    <material name="silver"/>
  </visual>
  <collision>
    <origin xyz="-0.08025 -0.000501 0.2451" rpy="0 0 0"/>
    <geometry>
      <mesh filename="package://new_meta_R_V22_description/meshes/link3_1.stl" scale="0.001 0.001 0.001"/>
    </geometry>
  </collision>
</link>

<link name="link4_1">
  <inertial>
    <origin xyz="-2.4276151635652977e-05 -0.03132928017093527 0.06620759675733753" rpy="0 0 0"/>
    <mass value="0.05424565895462734"/>
    <inertia ixx="2.7e-05" iyy="2e-05" izz="1.5e-05" ixy="-0.0" iyz="3e-06" ixz="0.0"/>
  </inertial>
  <visual>
    <origin xyz="-0.00425 -0.020501 0.2451" rpy="0 0 0"/>
    <geometry>
      <mesh filename="package://new_meta_R_V22_description/meshes/link4_1.stl" scale="0.001 0.001 0.001"/>
    </geometry>
    <material name="silver"/>
  </visual>
  <collision>
    <origin xyz="-0.00425 -0.020501 0.2451" rpy="0 0 0"/>
    <geometry>
      <mesh filename="package://new_meta_R_V22_description/meshes/link4_1.stl" scale="0.001 0.001 0.001"/>
    </geometry>
  </collision>
</link>

<link name="link5_1">
  <inertial>
    <origin xyz="2.6952233662754302e-05 0.0009180760301000449 0.06038225277132726" rpy="0 0 0"/>
    <mass value="0.048960278504967064"/>
    <inertia ixx="2.2e-05" iyy="1.9e-05" izz="8e-06" ixy="-0.0" iyz="-0.0" ixz="0.0"/>
  </inertial>
  <visual>
    <origin xyz="-0.00425 -0.001001 0.154" rpy="0 0 0"/>
    <geometry>
      <mesh filename="package://new_meta_R_V22_description/meshes/link5_1.stl" scale="0.001 0.001 0.001"/>
    </geometry>
    <material name="silver"/>
  </visual>
  <collision>
    <origin xyz="-0.00425 -0.001001 0.154" rpy="0 0 0"/>
    <geometry>
      <mesh filename="package://new_meta_R_V22_description/meshes/link5_1.stl" scale="0.001 0.001 0.001"/>
    </geometry>
  </collision>
</link>

<link name="link6_1">
  <inertial>
    <origin xyz="-0.005176099720724601 -0.021222498167263782 0.06178294796844156" rpy="0 0 0"/>
    <mass value="0.062198742572139885"/>
    <inertia ixx="3.7e-05" iyy="4.3e-05" izz="2.6e-05" ixy="0.0" iyz="0.0" ixz="3e-06"/>
  </inertial>
  <visual>
    <origin xyz="-0.00425 -0.022001 0.076" rpy="0 0 0"/>
    <geometry>
      <mesh filename="package://new_meta_R_V22_description/meshes/link6_1.stl" scale="0.001 0.001 0.001"/>
    </geometry>
    <material name="silver"/>
  </visual>
  <collision>
    <origin xyz="-0.00425 -0.022001 0.076" rpy="0 0 0"/>
    <geometry>
      <mesh filename="package://new_meta_R_V22_description/meshes/link6_1.stl" scale="0.001 0.001 0.001"/>
    </geometry>
  </collision>
</link>

<link name="link8_1">
  <inertial>
    <origin xyz="5.849098982935175e-14 5.990998358950125e-07 0.0012867771027079444" rpy="0 0 0"/>
    <mass value="0.0006569528428977336"/>
    <inertia ixx="0.0" iyy="0.0" izz="0.0" ixy="-0.0" iyz="-0.0" ixz="-0.0"/>
  </inertial>
  <visual>
    <origin xyz="0.0 -1e-06 0.004" rpy="0 0 0"/>
    <geometry>
      <mesh filename="package://new_meta_R_V22_description/meshes/link8_1.stl" scale="0.001 0.001 0.001"/>
    </geometry>
    <material name="silver"/>
  </visual>
  <collision>
    <origin xyz="0.0 -1e-06 0.004" rpy="0 0 0"/>
    <geometry>
      <mesh filename="package://new_meta_R_V22_description/meshes/link8_1.stl" scale="0.001 0.001 0.001"/>
    </geometry>
  </collision>
</link>

<joint name="joint1" type="revolute">
  <origin xyz="0.19135 1e-06 -0.2571" rpy="0 0 0"/>
  <parent link="base_link"/>
  <child link="link1_1"/>
  <axis xyz="-1.0 -0.0 0.0"/>
</joint>

<joint name="joint2" type="revolute">
  <origin xyz="-0.02 0.02 0.012" rpy="0 0 0"/>
  <parent link="link1_1"/>
  <child link="link2_1"/>
  <axis xyz="-0.0 1.0 0.0"/>
</joint>

<joint name="joint3" type="revolute">
  <origin xyz="-0.0911 -0.0195 0.0" rpy="0 0 0"/>
  <parent link="link2_1"/>
  <child link="link3_1"/>
  <axis xyz="-1.0 -0.0 0.0"/>
</joint>

<joint name="joint4" type="revolute">
  <origin xyz="-0.076 0.02 0.0" rpy="0 0 0"/>
  <parent link="link3_1"/>
  <child link="link4_1"/>
  <axis xyz="-0.0 1.0 0.0"/>
</joint>

<joint name="joint5" type="revolute">
  <origin xyz="0.0 -0.0195 0.0911" rpy="0 0 0"/>
  <parent link="link4_1"/>
  <child link="link5_1"/>
  <axis xyz="0.0 -0.0 1.0"/>
</joint>

<joint name="joint6" type="revolute">
  <origin xyz="0.0 0.021 0.078" rpy="0 0 0"/>
  <parent link="link5_1"/>
  <child link="link6_1"/>
  <axis xyz="-0.0 1.0 0.0"/>
</joint>

<joint name="joint7" type="revolute">
  <origin xyz="-0.00425 -0.022 0.072" rpy="0 0 0"/>
  <parent link="link6_1"/>
  <child link="link8_1"/>
  <axis xyz="0.0 -0.0 1.0"/>
  <limit upper="0.0" lower="0.0" effort="100" velocity="100"/>
</joint>

</robot>
