<?xml version="1.0" ?>
<robot name="new_meta_L_V22" xmlns:xacro="http://www.ros.org/wiki/xacro">

<xacro:include filename="$(find new_meta_L_V22_description)/urdf/materials.xacro" />
<xacro:include filename="$(find new_meta_L_V22_description)/urdf/new_meta_L_V22.trans" />
<xacro:include filename="$(find new_meta_L_V22_description)/urdf/new_meta_L_V22.gazebo" />
<link name="base_link">
  <inertial>
    <origin xyz="-0.19825177941437963 -0.010797344885369833 -0.2520181176479614" rpy="0 0 0"/>
    <mass value="0.042998534330391996"/>
    <inertia ixx="1.1e-05" iyy="7e-06" izz="1.2e-05" ixy="-0.0" iyz="-0.0" ixz="0.0"/>
  </inertial>
  <visual>
    <origin xyz="0 0 0" rpy="0 0 0"/>
    <geometry>
      <mesh filename="package://new_meta_L_V22_description/meshes/base_link.stl" scale="0.001 0.001 0.001"/>
    </geometry>
    <material name="silver"/>
  </visual>
  <collision>
    <origin xyz="0 0 0" rpy="0 0 0"/>
    <geometry>
      <mesh filename="package://new_meta_L_V22_description/meshes/base_link.stl" scale="0.001 0.001 0.001"/>
    </geometry>
  </collision>
</link>

<link name="link2_1">
  <inertial>
    <origin xyz="0.06591512238420348 -0.03126644490339182 2.380216388211953e-05" rpy="0 0 0"/>
    <mass value="0.054538745902098215"/>
    <inertia ixx="1.5e-05" iyy="2.1e-05" izz="2.8e-05" ixy="3e-06" iyz="0.0" ixz="-0.0"/>
  </inertial>
  <visual>
    <origin xyz="0.159077 -0.020987 0.240018" rpy="0 0 0"/>
    <geometry>
      <mesh filename="package://new_meta_L_V22_description/meshes/link2_1.stl" scale="0.001 0.001 0.001"/>
    </geometry>
    <material name="silver"/>
  </visual>
  <collision>
    <origin xyz="0.159077 -0.020987 0.240018" rpy="0 0 0"/>
    <geometry>
      <mesh filename="package://new_meta_L_V22_description/meshes/link2_1.stl" scale="0.001 0.001 0.001"/>
    </geometry>
  </collision>
</link>

<link name="link3_1">
  <inertial>
    <origin xyz="0.059693260705994095 0.000722733539306044 -2.4772875983070097e-06" rpy="0 0 0"/>
    <mass value="0.049075913621061326"/>
    <inertia ixx="8e-06" iyy="1.9e-05" izz="2.1e-05" ixy="-0.0" iyz="-0.0" ixz="-0.0"/>
  </inertial>
  <visual>
    <origin xyz="0.067977 -0.001487 0.240018" rpy="0 0 0"/>
    <geometry>
      <mesh filename="package://new_meta_L_V22_description/meshes/link3_1.stl" scale="0.001 0.001 0.001"/>
    </geometry>
    <material name="silver"/>
  </visual>
  <collision>
    <origin xyz="0.067977 -0.001487 0.240018" rpy="0 0 0"/>
    <geometry>
      <mesh filename="package://new_meta_L_V22_description/meshes/link3_1.stl" scale="0.001 0.001 0.001"/>
    </geometry>
  </collision>
</link>

<link name="link4_1">
  <inertial>
    <origin xyz="-2.4264759047546575e-05 -0.031330015139573855 0.06620725354959842" rpy="0 0 0"/>
    <mass value="0.05424565895462734"/>
    <inertia ixx="2.7e-05" iyy="2e-05" izz="1.5e-05" ixy="-0.0" iyz="3e-06" ixz="0.0"/>
  </inertial>
  <visual>
    <origin xyz="-0.008023 -0.021487 0.240018" rpy="0 0 0"/>
    <geometry>
      <mesh filename="package://new_meta_L_V22_description/meshes/link4_1.stl" scale="0.001 0.001 0.001"/>
    </geometry>
    <material name="silver"/>
  </visual>
  <collision>
    <origin xyz="-0.008023 -0.021487 0.240018" rpy="0 0 0"/>
    <geometry>
      <mesh filename="package://new_meta_L_V22_description/meshes/link4_1.stl" scale="0.001 0.001 0.001"/>
    </geometry>
  </collision>
</link>

<link name="link5_1">
  <inertial>
    <origin xyz="2.6963626246268024e-05 0.0009173410614952502 0.06038190956358262" rpy="0 0 0"/>
    <mass value="0.048960278504967064"/>
    <inertia ixx="2.2e-05" iyy="1.9e-05" izz="8e-06" ixy="-0.0" iyz="-0.0" ixz="0.0"/>
  </inertial>
  <visual>
    <origin xyz="-0.008023 -0.001987 0.148918" rpy="0 0 0"/>
    <geometry>
      <mesh filename="package://new_meta_L_V22_description/meshes/link5_1.stl" scale="0.001 0.001 0.001"/>
    </geometry>
    <material name="silver"/>
  </visual>
  <collision>
    <origin xyz="-0.008023 -0.001987 0.148918" rpy="0 0 0"/>
    <geometry>
      <mesh filename="package://new_meta_L_V22_description/meshes/link5_1.stl" scale="0.001 0.001 0.001"/>
    </geometry>
  </collision>
</link>

<link name="link6_1">
  <inertial>
    <origin xyz="-0.005176088328145919 -0.021223233135887573 0.061782604760698336" rpy="0 0 0"/>
    <mass value="0.062198742572140045"/>
    <inertia ixx="3.7e-05" iyy="4.3e-05" izz="2.6e-05" ixy="0.0" iyz="0.0" ixz="3e-06"/>
  </inertial>
  <visual>
    <origin xyz="-0.008023 -0.022987 0.070918" rpy="0 0 0"/>
    <geometry>
      <mesh filename="package://new_meta_L_V22_description/meshes/link6_1.stl" scale="0.001 0.001 0.001"/>
    </geometry>
    <material name="silver"/>
  </visual>
  <collision>
    <origin xyz="-0.008023 -0.022987 0.070918" rpy="0 0 0"/>
    <geometry>
      <mesh filename="package://new_meta_L_V22_description/meshes/link6_1.stl" scale="0.001 0.001 0.001"/>
    </geometry>
  </collision>
</link>

<link name="link1_1">
  <inertial>
    <origin xyz="0.018447169578158618 0.000754963204374864 0.00019728933916640656" rpy="0 0 0"/>
    <mass value="0.04698163433943534"/>
    <inertia ixx="1.4e-05" iyy="1.3e-05" izz="9e-06" ixy="-0.0" iyz="-0.0" ixz="-0.0"/>
  </inertial>
  <visual>
    <origin xyz="0.179077 -0.000987 0.252018" rpy="0 0 0"/>
    <geometry>
      <mesh filename="package://new_meta_L_V22_description/meshes/link1_1.stl" scale="0.001 0.001 0.001"/>
    </geometry>
    <material name="silver"/>
  </visual>
  <collision>
    <origin xyz="0.179077 -0.000987 0.252018" rpy="0 0 0"/>
    <geometry>
      <mesh filename="package://new_meta_L_V22_description/meshes/link1_1.stl" scale="0.001 0.001 0.001"/>
    </geometry>
  </collision>
</link>

<link name="link8_1">
  <inertial>
    <origin xyz="-1.3754372895323497e-07 -2.8480503321036757e-07 0.0012864338949660423" rpy="0 0 0"/>
    <mass value="0.0006569528428977334"/>
    <inertia ixx="0.0" iyy="0.0" izz="0.0" ixy="-0.0" iyz="-0.0" ixz="0.0"/>
  </inertial>
  <visual>
    <origin xyz="-0.003773 -0.000987 -0.001082" rpy="0 0 0"/>
    <geometry>
      <mesh filename="package://new_meta_L_V22_description/meshes/link8_1.stl" scale="0.001 0.001 0.001"/>
    </geometry>
    <material name="silver"/>
  </visual>
  <collision>
    <origin xyz="-0.003773 -0.000987 -0.001082" rpy="0 0 0"/>
    <geometry>
      <mesh filename="package://new_meta_L_V22_description/meshes/link8_1.stl" scale="0.001 0.001 0.001"/>
    </geometry>
  </collision>
</link>

<joint name="joint2" type="revolute">
  <origin xyz="0.02 0.02 0.012" rpy="0 0 0"/>
  <parent link="link1_1"/>
  <child link="link2_1"/>
  <axis xyz="0.0 1.0 -0.0"/>
</joint>

<joint name="joint3" type="revolute">
  <origin xyz="0.0911 -0.0195 0.0" rpy="0 0 0"/>
  <parent link="link2_1"/>
  <child link="link3_1"/>
  <axis xyz="1.0 -0.0 -0.0"/>
</joint>

<joint name="joint4" type="revolute">
  <origin xyz="0.076 0.02 0.0" rpy="0 0 0"/>
  <parent link="link3_1"/>
  <child link="link4_1"/>
  <axis xyz="0.0 1.0 -0.0"/>
</joint>

<joint name="joint5" type="revolute">
  <origin xyz="0.0 -0.0195 0.0911" rpy="0 0 0"/>
  <parent link="link4_1"/>
  <child link="link5_1"/>
  <axis xyz="0.0 0.0 1.0"/>
</joint>

<joint name="joint6" type="revolute">
  <origin xyz="0.0 0.021 0.078" rpy="0 0 0"/>
  <parent link="link5_1"/>
  <child link="link6_1"/>
  <axis xyz="0.0 1.0 -0.0"/>
</joint>

<joint name="joint1" type="revolute">
  <origin xyz="-0.179077 0.000987 -0.252018" rpy="0 0 0"/>
  <parent link="base_link"/>
  <child link="link1_1"/>
  <axis xyz="1.0 -0.0 -0.0"/>
</joint>

<joint name="joint7" type="revolute">
  <origin xyz="-0.00425 -0.022 0.072" rpy="0 0 0"/>
  <parent link="link6_1"/>
  <child link="link8_1"/>
  <axis xyz="0.0 0.0 1.0"/>
  <limit upper="0.0" lower="0.0" effort="100" velocity="100"/>
</joint>

</robot>
